<?xml version='1.0' encoding='utf-8'?>
<robot name="lettuce">

    <link name="link0">
      <inertial>
        <origin xyz="0 0 0" rpy="0 0 0" />
        <mass value="0.0005" />
        <inertia ixx="0.0" iyy="0.0" izz="0.0" ixy="0" ixz="0" iyz="0" />
      </inertial>
    </link>
    <link name="link1">
      <inertial>
        <origin xyz="0 0 0" rpy="0 0 0" />
        <mass value="1e-10" />
        <inertia ixx="1e-10" iyy="1e-10" izz="1e-10" ixy="0" ixz="0" iyz="0" />
      </inertial>
    </link>
    <link name="link2">
      <inertial>
        <origin xyz="0 0 0" rpy="0 0 0" />
        <mass value="1e-10" />
        <inertia ixx="1e-10" iyy="1e-10" izz="1e-10" ixy="0" ixz="0" iyz="0" />
      </inertial>
    </link>
    <link name="link3">
      <inertial>
        <origin xyz="0 0 0" rpy="0 0 0" />
        <mass value="1e-10" />
        <inertia ixx="1e-10" iyy="1e-10" izz="1e-10" ixy="0" ixz="0" iyz="0" />
      </inertial>
    </link>
      <link name="link4">
      <inertial>
        <origin xyz="0 0 0" rpy="0 0 0" />
        <mass value="1e-10" />
        <inertia ixx="1e-10" iyy="1e-10" izz="1e-10" ixy="0" ixz="0" iyz="0" />
      </inertial>
    </link>
    <link name="link5">
      <inertial>
        <origin xyz="0 0 0" rpy="0 0 0" />
        <mass value="1e-10" />
        <inertia ixx="1e-10" iyy="1e-10" izz="1e-10" ixy="0" ixz="0" iyz="0" />
      </inertial>
    </link>
    <link name="link6">
      <inertial>
        <origin xyz="0 0 0" rpy="0 0 0" />
        <mass value="0.173" />
        <inertia ixx="7.821e-5" iyy="7.821e-5" izz="1.384e-4" ixy="0" ixz="0" iyz="0" />
      </inertial>
      <visual>
        <geometry>
          <mesh filename="../../../Gordon_the_robot/model/kitchen_objects/meshes/visual/Lettuce.obj" scale="1.0 1.0 1.0"/>
        </geometry>
      </visual>
     <!--  <collision>
        <origin xyz="0 0 0.00079375"/>
        <geometry>
          <box size="0.075 0.075 0.0015875"/>
        </geometry>
      </collision> -->
    </link>
    <link name="link7">
      <inertial>
        <origin xyz="0 0 0.00158" rpy="0 0 0" />
        <mass value="0.173" />
        <inertia ixx="7.821e-5" iyy="7.821e-5" izz="1.384e-4" ixy="0" ixz="0" iyz="0" />
      </inertial>
      <visual>
        <geometry>
          <mesh filename="../../../Gordon_the_robot/model/kitchen_objects/meshes/visual/Tomato.obj" scale="1.0 1.0 1.0"/>
        </geometry>
      </visual>
<!--       <collision>
        <origin xyz="0 0 0.00127"/>
        <geometry>
          <cylinder length="0.00254" radius="0.0015875"/>
        </geometry>
      </collision> -->
    </link>

    
    <joint name="joint1" type="prismatic">
      <origin xyz="0 0 0" rpy="0 0 0"/>
      <parent link="link0"/>
      <child link="link1"/>
      <axis xyz="0 0 1"/>
      <!-- <dynamics damping="0.0" friction="1"/> -->
      <limit effort="21.3" lower="-100" upper="100" velocity="21.3"/>
    </joint>
    <joint name="joint2" type="prismatic">
      <origin xyz="0 0 0" rpy="0 0 0"/>
      <parent link="link1"/>
      <child link="link2"/>
      <axis xyz="0 1 0"/>
      <!-- <dynamics damping="0.0" friction="1"/> -->
      <limit effort="21.3" lower="-100" upper="100" velocity="21.3"/>
    </joint>
    <joint name="joint3" type="prismatic">
      <origin xyz="0 0 0" rpy="0 0 0"/>
      <parent link="link2"/>
      <child link="link3"/>
      <axis xyz="1 0 0"/>
      <limit effort="21.3" lower="-100" upper="100" velocity="21.3"/>
    </joint>
    <joint name="joint4" type="revolute">
      <origin xyz="0 0 0" rpy="0 0 0"/>
      <parent link="link3"/>
      <child link="link4"/>
        <axis xyz="1 0 0"/>
        <dynamics damping="20.0" friction="2.0"/>
      <limit effort="21.3" lower="0" upper="6.28" velocity="21.3"/>
    </joint>
    <joint name="joint5" type="revolute">
      <origin xyz="0 0 0" rpy="0 0 0"/>
      <parent link="link4"/>
      <child link="link5"/>
        <axis xyz="0 1 0"/>
        <dynamics damping="20.0" friction="2.0"/>
      <limit effort="21.3" lower="0" upper="6.28" velocity="21.3"/>
    </joint>
    <joint name="joint6" type="revolute">
      <origin xyz="0 0 0" rpy="0 0 0"/>
      <parent link="link5"/>
      <child link="link6"/>
        <axis xyz="0 0 1"/>
        <dynamics damping="20.0" friction="2.0"/>
      <limit effort="21.3" lower="0" upper="6.28" velocity="21.3"/>
    </joint>
    <joint name="joint7" type="fixed">
      <origin xyz="0 0 0" rpy="0 0 0"/>
      <parent link="link6"/>
      <child link="link7"/>
        <axis xyz="0 0 1"/>
        <dynamics damping="20.0" friction="2.0"/>
      <limit effort="21.3" lower="0" upper="6.28" velocity="21.3"/>
    </joint>
  
</robot>

</xml>
